Workbook

Sheet Summary
A1: Dish Cost — Summary
A2: Cost % = (ingredient cost per container + packaging) ÷ selling price. Prices exclude VAT; delivery app commission not included.
A4: Dish | B4: Section | C4: Single | H4: Small | M4: Medium | R4: Large
C5: Cost | D5: Store price | E5: Store % | F5: Delivery price | G5: Delivery % | H5: Cost | I5: Store price | J5: Store % | K5: Delivery price | L5: Delivery % | M5: Cost | N5: Store price | O5: Store % | P5: Delivery price | Q5: Delivery % | R5: Cost | S5: Store price | T5: Store % | U5: Delivery price | V5: Delivery %
A6: Fool & Cheese | B6: Eggs & fool | H6: ='Fool & Cheese'!C34 -> 0.45620846 | I6: ='Fool & Cheese'!C35 -> 1.5 | J6: ='Fool & Cheese'!C36 -> 0.30413897 | K6: =IF('Fool & Cheese'!C37="","",'Fool & Cheese'!C37) -> 1.9 | L6: ='Fool & Cheese'!C38 -> 0.24010972 | M6: ='Fool & Cheese'!D34 -> 0.89191692 | N6: ='Fool & Cheese'!D35 -> 2.8 | O6: ='Fool & Cheese'!D36 -> 0.31854176 | P6: =IF('Fool & Cheese'!D37="","",'Fool & Cheese'!D37) -> 3.4 | Q6: ='Fool & Cheese'!D38 -> 0.26232851 | R6: ='Fool & Cheese'!E34 -> 1.8111005 | S6: ='Fool & Cheese'!E35 -> 5.4 | T6: ='Fool & Cheese'!E36 -> 0.33538898 | U6: =IF('Fool & Cheese'!E37="","",'Fool & Cheese'!E37) -> 6.4 | V6: ='Fool & Cheese'!E38 -> 0.28298446
A7: Fasolya | B7: Eggs & fool | H7: =Fasolya!C34 -> 0.40906598 | I7: =Fasolya!C35 -> 1.3 | J7: =Fasolya!C36 -> 0.31466614 | K7: =IF(Fasolya!C37="","",Fasolya!C37) -> 1.7 | L7: =Fasolya!C38 -> 0.24062705 | M7: =Fasolya!D34 -> 0.79763196 | N7: =Fasolya!D35 -> 2.4 | O7: =Fasolya!D36 -> 0.33234665 | P7: =IF(Fasolya!D37="","",Fasolya!D37) -> 3 | Q7: =Fasolya!D38 -> 0.26587732 | R7: =Fasolya!E34 -> 1.6225306 | S7: =Fasolya!E35 -> 4.6 | T7: =Fasolya!E36 -> 0.35272404 | U7: =IF(Fasolya!E37="","",Fasolya!E37) -> 5.6 | V7: =Fasolya!E38 -> 0.2897376
A8: S.Egg Bin Aqool | B8: Eggs & fool | H8: ='S.Egg Bin Aqool'!C37 -> 0.43909871 | I8: ='S.Egg Bin Aqool'!C38 -> 1.6 | J8: ='S.Egg Bin Aqool'!C39 -> 0.27443669 | K8: =IF('S.Egg Bin Aqool'!C40="","",'S.Egg Bin Aqool'!C40) -> 2 | L8: ='S.Egg Bin Aqool'!C41 -> 0.21954935 | M8: ='S.Egg Bin Aqool'!D37 -> 0.85769741 | N8: ='S.Egg Bin Aqool'!D38 -> 3 | O8: ='S.Egg Bin Aqool'!D39 -> 0.28589914 | P8: =IF('S.Egg Bin Aqool'!D40="","",'S.Egg Bin Aqool'!D40) -> 3.6 | Q8: ='S.Egg Bin Aqool'!D41 -> 0.23824928 | R8: ='S.Egg Bin Aqool'!E37 -> 1.7426615 | S8: ='S.Egg Bin Aqool'!E38 -> 5.6 | T8: ='S.Egg Bin Aqool'!E39 -> 0.31118955 | U8: =IF('S.Egg Bin Aqool'!E40="","",'S.Egg Bin Aqool'!E40) -> 6.8 | V8: ='S.Egg Bin Aqool'!E41 -> 0.25627375
A9: Egg Shakshoka | B9: Eggs & fool | H9: ='Egg Shakshoka'!C31 -> 0.2567158 | I9: ='Egg Shakshoka'!C32 -> 1.2 | J9: ='Egg Shakshoka'!C33 -> 0.21392983 | K9: =IF('Egg Shakshoka'!C34="","",'Egg Shakshoka'!C34) -> 1.6 | L9: ='Egg Shakshoka'!C35 -> 0.16044737 | M9: ='Egg Shakshoka'!D31 -> 0.49293159 | N9: ='Egg Shakshoka'!D32 -> 2.2 | O9: ='Egg Shakshoka'!D33 -> 0.22405981 | P9: =IF('Egg Shakshoka'!D34="","",'Egg Shakshoka'!D34) -> 2.8 | Q9: ='Egg Shakshoka'!D35 -> 0.176047 | R9: ='Egg Shakshoka'!E31 -> 1.0131298 | S9: ='Egg Shakshoka'!E32 -> 4.2 | T9: ='Egg Shakshoka'!E33 -> 0.24122139 | U9: =IF('Egg Shakshoka'!E34="","",'Egg Shakshoka'!E34) -> 5 | V9: ='Egg Shakshoka'!E35 -> 0.20262597
A10: Egg Vegatable | B10: Eggs & fool | H10: ='Egg Vegatable'!C34 -> 0.27302865 | I10: ='Egg Vegatable'!C35 -> 1.2 | J10: ='Egg Vegatable'!C36 -> 0.22752387 | K10: =IF('Egg Vegatable'!C37="","",'Egg Vegatable'!C37) -> 1.6 | L10: ='Egg Vegatable'!C38 -> 0.1706429 | M10: ='Egg Vegatable'!D34 -> 0.52555729 | N10: ='Egg Vegatable'!D35 -> 2.2 | O10: ='Egg Vegatable'!D36 -> 0.23888968 | P10: =IF('Egg Vegatable'!D37="","",'Egg Vegatable'!D37) -> 2.8 | Q10: ='Egg Vegatable'!D38 -> 0.18769903 | R10: ='Egg Vegatable'!E34 -> 1.0783812 | S10: ='Egg Vegatable'!E35 -> 4.2 | T10: ='Egg Vegatable'!E36 -> 0.25675744 | U10: =IF('Egg Vegatable'!E37="","",'Egg Vegatable'!E37) -> 5 | V10: ='Egg Vegatable'!E38 -> 0.21567625
A11: Egg Makhalama | B11: Eggs & fool | H11: ='Egg Makhalama'!C34 -> 0.27681915 | I11: ='Egg Makhalama'!C35 -> 1.4 | J11: ='Egg Makhalama'!C36 -> 0.19772796 | K11: =IF('Egg Makhalama'!C37="","",'Egg Makhalama'!C37) -> 1.85 | L11: ='Egg Makhalama'!C38 -> 0.14963197 | M11: ='Egg Makhalama'!D34 -> 0.54337829 | N11: ='Egg Makhalama'!D35 -> 2.6 | O11: ='Egg Makhalama'!D36 -> 0.20899165 | P11: =IF('Egg Makhalama'!D37="","",'Egg Makhalama'!D37) -> 3.2 | Q11: ='Egg Makhalama'!D38 -> 0.16980572 | R11: ='Egg Makhalama'!E34 -> 1.1012232 | S11: ='Egg Makhalama'!E35 -> 5 | T11: ='Egg Makhalama'!E36 -> 0.22024465 | U11: =IF('Egg Makhalama'!E37="","",'Egg Makhalama'!E37) -> 6 | V11: ='Egg Makhalama'!E38 -> 0.18353721
A12: Egg Cheese | B12: Eggs & fool | H12: ='Egg Cheese'!C23 -> 0.33889824 | I12: ='Egg Cheese'!C24 -> 1.3 | J12: ='Egg Cheese'!C25 -> 0.26069095 | K12: =IF('Egg Cheese'!C26="","",'Egg Cheese'!C26) -> 1.7 | L12: ='Egg Cheese'!C27 -> 0.1993519 | M12: ='Egg Cheese'!D23 -> 0.65729647 | N12: ='Egg Cheese'!D24 -> 2.4 | O12: ='Egg Cheese'!D25 -> 0.27387353 | P12: =IF('Egg Cheese'!D26="","",'Egg Cheese'!D26) -> 3 | Q12: ='Egg Cheese'!D27 -> 0.21909882 | R12: ='Egg Cheese'!E23 -> 1.3418596 | S12: ='Egg Cheese'!E24 -> 4.6 | T12: ='Egg Cheese'!E25 -> 0.29170861 | U12: =IF('Egg Cheese'!E26="","",'Egg Cheese'!E26) -> 5.6 | V12: ='Egg Cheese'!E27 -> 0.23961779
A13: Egg Fried | B13: Eggs & fool | H13: ='Egg Fried'!C22 -> 0.21722 | I13: ='Egg Fried'!C23 -> 0.9 | J13: ='Egg Fried'!C24 -> 0.24135556 | K13: =IF('Egg Fried'!C25="","",'Egg Fried'!C25) -> 1.2 | L13: ='Egg Fried'!C26 -> 0.18101667 | M13: ='Egg Fried'!D22 -> 0.41394 | N13: ='Egg Fried'!D23 -> 1.7 | O13: ='Egg Fried'!D24 -> 0.24349412 | P13: =IF('Egg Fried'!D25="","",'Egg Fried'!D25) -> 2.2 | Q13: ='Egg Fried'!D26 -> 0.18815455 | R13: ='Egg Fried'!E22 -> 0.85514667 | S13: ='Egg Fried'!E23 -> 3.3 | T13: ='Egg Fried'!E24 -> 0.25913535 | U13: =IF('Egg Fried'!E25="","",'Egg Fried'!E25) -> 3.8 | V13: ='Egg Fried'!E26 -> 0.2250386
A14: Egg Eyoon | B14: Eggs & fool | H14: ='Egg Eyoon'!C22 -> 0.21722 | I14: ='Egg Eyoon'!C23 -> 0.9 | J14: ='Egg Eyoon'!C24 -> 0.24135556 | K14: =IF('Egg Eyoon'!C25="","",'Egg Eyoon'!C25) -> 1.2 | L14: ='Egg Eyoon'!C26 -> 0.18101667 | M14: ='Egg Eyoon'!D22 -> 0.41394 | N14: ='Egg Eyoon'!D23 -> 1.7 | O14: ='Egg Eyoon'!D24 -> 0.24349412 | P14: =IF('Egg Eyoon'!D25="","",'Egg Eyoon'!D25) -> 2.2 | Q14: ='Egg Eyoon'!D26 -> 0.18815455 | R14: ='Egg Eyoon'!E22 -> 0.85514667 | S14: ='Egg Eyoon'!E23 -> 3.3 | T14: ='Egg Eyoon'!E24 -> 0.25913535 | U14: =IF('Egg Eyoon'!E25="","",'Egg Eyoon'!E25) -> 3.8 | V14: ='Egg Eyoon'!E26 -> 0.2250386
A15: Egg & Fasolya | B15: Eggs & fool | H15: ='Egg & Fasolya'!C35 -> 0.47906598 | I15: ='Egg & Fasolya'!C36 -> 1.6 | J15: ='Egg & Fasolya'!C37 -> 0.29941624 | K15: =IF('Egg & Fasolya'!C38="","",'Egg & Fasolya'!C38) -> 2 | L15: ='Egg & Fasolya'!C39 -> 0.23953299 | M15: ='Egg & Fasolya'!D35 -> 0.93763196 | N15: ='Egg & Fasolya'!D36 -> 3 | O15: ='Egg & Fasolya'!D37 -> 0.31254399 | P15: =IF('Egg & Fasolya'!D38="","",'Egg & Fasolya'!D38) -> 3.6 | Q15: ='Egg & Fasolya'!D39 -> 0.26045332 | R15: ='Egg & Fasolya'!E35 -> 1.9025306 | S15: ='Egg & Fasolya'!E36 -> 5.6 | T15: ='Egg & Fasolya'!E37 -> 0.3397376 | U15: =IF('Egg & Fasolya'!E38="","",'Egg & Fasolya'!E38) -> 6.8 | V15: ='Egg & Fasolya'!E39 -> 0.27978391
A16: Egg & Tomato | B16: Eggs & fool | H16: ='Egg & Tomato'!C29 -> 0.2900575 | I16: ='Egg & Tomato'!C30 -> 1.2 | J16: ='Egg & Tomato'!C31 -> 0.24171458 | K16: =IF('Egg & Tomato'!C32="","",'Egg & Tomato'!C32) -> 1.6 | L16: ='Egg & Tomato'!C33 -> 0.18128594 | M16: ='Egg & Tomato'!D29 -> 0.559615 | N16: ='Egg & Tomato'!D30 -> 2.2 | O16: ='Egg & Tomato'!D31 -> 0.25437045 | P16: =IF('Egg & Tomato'!D32="","",'Egg & Tomato'!D32) -> 2.8 | Q16: ='Egg & Tomato'!D33 -> 0.1998625 | R16: ='Egg & Tomato'!E29 -> 1.1464967 | S16: ='Egg & Tomato'!E30 -> 4.2 | T16: ='Egg & Tomato'!E31 -> 0.2729754 | U16: =IF('Egg & Tomato'!E32="","",'Egg & Tomato'!E32) -> 5 | V16: ='Egg & Tomato'!E33 -> 0.22929933
A17: Fool | B17: Eggs & fool | H17: =Fool!C34 -> 0.42244376 | I17: =Fool!C35 -> 1.4 | J17: =Fool!C36 -> 0.30174554 | K17: =IF(Fool!C37="","",Fool!C37) -> 1.7 | L17: =Fool!C38 -> 0.24849633 | M17: =Fool!D34 -> 0.82438751 | N17: =Fool!D35 -> 2.6 | O17: =Fool!D36 -> 0.31707212 | P17: =IF(Fool!D37="","",Fool!D37) -> 3 | Q17: =Fool!D38 -> 0.27479584 | R17: =Fool!E34 -> 1.6760417 | S17: =Fool!E35 -> 5 | T17: =Fool!E36 -> 0.33520834 | U17: =IF(Fool!E37="","",Fool!E37) -> 5.6 | V17: =Fool!E38 -> 0.29929316
A18: Rice & Chicken | B18: Traditional | H18: ='Rice & Chicken'!C37 -> 0.49338804 | I18: ='Rice & Chicken'!C38 -> 1.2 | J18: ='Rice & Chicken'!C39 -> 0.4111567 | K18: =IF('Rice & Chicken'!C40="","",'Rice & Chicken'!C40) -> 1.2 | L18: ='Rice & Chicken'!C41 -> 0.4111567 | M18: ='Rice & Chicken'!D37 -> 0.88418007 | N18: ='Rice & Chicken'!D38 -> 2.3 | O18: ='Rice & Chicken'!D39 -> 0.38442612 | P18: =IF('Rice & Chicken'!D40="","",'Rice & Chicken'!D40) -> 2.3 | Q18: ='Rice & Chicken'!D41 -> 0.38442612 | R18: ='Rice & Chicken'!E37 -> 1.7444601 | S18: ='Rice & Chicken'!E38 -> 4.4 | T18: ='Rice & Chicken'!E39 -> 0.39646821 | U18: =IF('Rice & Chicken'!E40="","",'Rice & Chicken'!E40) -> 4.4 | V18: ='Rice & Chicken'!E41 -> 0.39646821
A19: Black Eye Beans | B19: Traditional | C19: ='Black Eye Beans'!C23 -> 0.087489063 | D19: ='Black Eye Beans'!C24 -> 0.4 | E19: ='Black Eye Beans'!C25 -> 0.21872266 | F19: =IF('Black Eye Beans'!C26="","",'Black Eye Beans'!C26) -> 0.4 | G19: ='Black Eye Beans'!C27 -> 0.21872266 | H19: ='Black Eye Beans'!D23 -> 0.10885208 | I19: ='Black Eye Beans'!D24 -> 0.6 | J19: ='Black Eye Beans'!D25 -> 0.18142014 | K19: =IF('Black Eye Beans'!D26="","",'Black Eye Beans'!D26) -> 0.75 | L19: ='Black Eye Beans'!D27 -> 0.14513611 | M19: ='Black Eye Beans'!E23 -> 0.19720417 | N19: ='Black Eye Beans'!E24 -> 1 | O19: ='Black Eye Beans'!E25 -> 0.19720417 | P19: =IF('Black Eye Beans'!E26="","",'Black Eye Beans'!E26) -> 1.3 | Q19: ='Black Eye Beans'!E27 -> 0.15169551 | R19: ='Black Eye Beans'!F23 -> 0.421675 | S19: ='Black Eye Beans'!F24 -> 1.8 | T19: ='Black Eye Beans'!F25 -> 0.23426389 | U19: =IF('Black Eye Beans'!F26="","",'Black Eye Beans'!F26) -> 2.2 | V19: ='Black Eye Beans'!F27 -> 0.19167045
A20: Nakhi | B20: Traditional | C20: =Nakhi!C24 -> 0.083955682 | D20: =Nakhi!C25 -> 0.4 | E20: =Nakhi!C26 -> 0.2098892 | F20: =IF(Nakhi!C27="","",Nakhi!C27) -> 0.4 | G20: =Nakhi!C28 -> 0.2098892 | H20: =Nakhi!D24 -> 0.10929917 | I20: =Nakhi!D25 -> 0.6 | J20: =Nakhi!D26 -> 0.18216529 | K20: =IF(Nakhi!D27="","",Nakhi!D27) -> 0.75 | L20: =Nakhi!D28 -> 0.14573223 | M20: =Nakhi!E24 -> 0.21047818 | N20: =Nakhi!E25 -> 1 | O20: =Nakhi!E26 -> 0.21047818 | P20: =IF(Nakhi!E27="","",Nakhi!E27) -> 1.2 | Q20: =Nakhi!E28 -> 0.17539848 | R20: =Nakhi!F24 -> 0.4028303 | S20: =Nakhi!F25 -> 1.8 | T20: =Nakhi!F26 -> 0.22379461 | U20: =IF(Nakhi!F27="","",Nakhi!F27) -> 2.2 | V20: =Nakhi!F28 -> 0.18310468
A21: Dall | B21: Traditional | C21: =Dall!C37 -> 0.1212619 | D21: =Dall!C38 -> 0.6 | E21: =Dall!C39 -> 0.20210316 | F21: =IF(Dall!C40="","",Dall!C40) -> 0.6 | G21: =Dall!C41 -> 0.20210316 | H21: =Dall!D37 -> 0.16403769 | I21: =Dall!D38 -> 1 | J21: =Dall!D39 -> 0.16403769 | K21: =IF(Dall!D40="","",Dall!D40) -> 1.35 | L21: =Dall!D41 -> 0.1215094 | M21: =Dall!E37 -> 0.25525653 | N21: =Dall!E38 -> 1.6 | O21: =Dall!E39 -> 0.15953533 | P21: =IF(Dall!E40="","",Dall!E40) -> 2.2 | Q21: =Dall!E41 -> 0.1160257 | R21: =Dall!F37 -> 0.53777973 | S21: =Dall!F38 -> 2.9 | T21: =Dall!F39 -> 0.18544129 | U21: =IF(Dall!F40="","",Dall!F40) -> 3.8 | V21: =Dall!F41 -> 0.14152098
A22: Bajela | B22: Traditional | C22: =Bajela!C24 -> 0.14612606 | D22: =Bajela!C25 -> 0.4 | E22: =Bajela!C26 -> 0.36531515 | F22: =IF(Bajela!C27="","",Bajela!C27) -> 0.4 | G22: =Bajela!C28 -> 0.36531515 | H22: =Bajela!D24 -> 0.22194343 | I22: =Bajela!D25 -> 0.6 | J22: =Bajela!D26 -> 0.36990572 | K22: =IF(Bajela!D27="","",Bajela!D27) -> 0.75 | L22: =Bajela!D28 -> 0.29592458 | M22: =Bajela!E24 -> 0.33611515 | N22: =Bajela!E25 -> 1 | O22: =Bajela!E26 -> 0.33611515 | P22: =IF(Bajela!E27="","",Bajela!E27) -> 1.2 | Q22: =Bajela!E28 -> 0.28009596 | R22: =Bajela!F24 -> 0.69949697 | S22: =Bajela!F25 -> 1.9 | T22: =Bajela!F26 -> 0.3681563 | U22: =IF(Bajela!F27="","",Bajela!F27) -> 2.2 | V22: =Bajela!F28 -> 0.31795317
A23: Harees | B23: Traditional | C23: =Harees!C25 -> 0.25394688 | D23: =Harees!C26 -> 0.6 | E23: =Harees!C27 -> 0.42324479 | F23: =IF(Harees!C28="","",Harees!C28) -> 0.6 | G23: =Harees!C29 -> 0.42324479 | H23: =Harees!D25 -> 0.32079583 | I23: =Harees!D26 -> 1 | J23: =Harees!D27 -> 0.32079583 | K23: =IF(Harees!D28="","",Harees!D28) -> 1.35 | L23: =Harees!D29 -> 0.23762654 | M23: =Harees!E25 -> 0.64109167 | N23: =Harees!E26 -> 1.6 | O23: =Harees!E27 -> 0.40068229 | P23: =IF(Harees!E28="","",Harees!E28) -> 2.4 | Q23: =Harees!E29 -> 0.26712153 | R23: =Harees!F25 -> 1.1375095 | S23: =Harees!F26 -> 2.9 | T23: =Harees!F27 -> 0.39224466 | U23: =IF(Harees!F28="","",Harees!F28) -> 4.4 | V23: =Harees!F29 -> 0.25852489
A24: Jareesh | B24: Traditional | H24: =Jareesh!C33 -> 0.18505557 | I24: =Jareesh!C34 -> 1 | J24: =Jareesh!C35 -> 0.18505557 | K24: =IF(Jareesh!C36="","",Jareesh!C36) -> 1 | L24: =Jareesh!C37 -> 0.18505557 | M24: =Jareesh!D33 -> 0.34300419 | N24: =Jareesh!D34 -> 1.6 | O24: =Jareesh!D35 -> 0.21437762 | P24: =IF(Jareesh!D36="","",Jareesh!D36) -> 1.6 | Q24: =Jareesh!D37 -> 0.21437762 | R24: =Jareesh!E33 -> 0.8689445 | S24: =Jareesh!E34 -> 2.9 | T24: =Jareesh!E35 -> 0.29963603 | U24: =IF(Jareesh!E36="","",Jareesh!E36) -> 2.9 | V24: =Jareesh!E37 -> 0.29963603
A25: Shilla | B25: Traditional | C25: =Shilla!C38 -> 0.11820006 | D25: =Shilla!C39 -> 0.6 | E25: =Shilla!C40 -> 0.19700009 | F25: =IF(Shilla!C41="","",Shilla!C41) -> 0.6 | G25: =Shilla!C42 -> 0.19700009 | H25: =Shilla!D38 -> 0.17307282 | I25: =Shilla!D39 -> 1 | J25: =Shilla!D40 -> 0.17307282 | K25: =IF(Shilla!D41="","",Shilla!D41) -> 1.35 | L25: =Shilla!D42 -> 0.12820209 | M25: =Shilla!E38 -> 0.27178586 | N25: =Shilla!E39 -> 1.6 | O25: =Shilla!E40 -> 0.16986616 | P25: =IF(Shilla!E41="","",Shilla!E41) -> 2.2 | Q25: =Shilla!E42 -> 0.12353903 | R25: =Shilla!F38 -> 0.52146692 | S25: =Shilla!F39 -> 2.9 | T25: =Shilla!F40 -> 0.17981618 | U25: =IF(Shilla!F41="","",Shilla!F41) -> 3.8 | V25: =Shilla!F42 -> 0.13722814
A26: Madrooba | B26: Traditional | C26: =Madrooba!C41 -> 0.16117204 | D26: =Madrooba!C42 -> 0.6 | E26: =Madrooba!C43 -> 0.26862006 | F26: =IF(Madrooba!C44="","",Madrooba!C44) -> 0.6 | G26: =Madrooba!C45 -> 0.26862006 | H26: =Madrooba!D41 -> 0.25850107 | I26: =Madrooba!D42 -> 1.1 | J26: =Madrooba!D43 -> 0.23500097 | K26: =IF(Madrooba!D44="","",Madrooba!D44) -> 1.35 | L26: =Madrooba!D45 -> 0.19148227 | M26: =Madrooba!E41 -> 0.49650213 | N26: =Madrooba!E42 -> 1.8 | O26: =Madrooba!E43 -> 0.27583452 | P26: =IF(Madrooba!E44="","",Madrooba!E44) -> 2.4 | Q26: =Madrooba!E45 -> 0.20687589 | R26: =Madrooba!F41 -> 1.0202709 | S26: =Madrooba!F42 -> 3.2 | T26: =Madrooba!F43 -> 0.31883467 | U26: =IF(Madrooba!F44="","",Madrooba!F44) -> 4.4 | V26: =Madrooba!F45 -> 0.23187976
A27: Beef Liver | B27: Main dishes | H27: ='Beef Liver'!C34 -> 0.51369327 | I27: ='Beef Liver'!C35 -> 1.8 | J27: ='Beef Liver'!C36 -> 0.28538515 | K27: =IF('Beef Liver'!C37="","",'Beef Liver'!C37) -> 2.2 | L27: ='Beef Liver'!C38 -> 0.23349694 | M27: ='Beef Liver'!D34 -> 1.0148785 | N27: ='Beef Liver'!D35 -> 3.4 | O27: ='Beef Liver'!D36 -> 0.29849369 | P27: =IF('Beef Liver'!D37="","",'Beef Liver'!D37) -> 4 | Q27: ='Beef Liver'!D38 -> 0.25371964 | R27: ='Beef Liver'!E34 -> 1.7514976 | S27: ='Beef Liver'!E35 -> 6.2 | T27: ='Beef Liver'!E36 -> 0.28249961 | U27: =IF('Beef Liver'!E37="","",'Beef Liver'!E37) -> 7.5 | V27: ='Beef Liver'!E38 -> 0.23353301
A28: Chicken Liver | B28: Main dishes | H28: ='Chicken Liver'!C40 -> 0.6053255 | I28: ='Chicken Liver'!C41 -> 2 | J28: ='Chicken Liver'!C42 -> 0.30266275 | K28: =IF('Chicken Liver'!C43="","",'Chicken Liver'!C43) -> 2.2 | L28: ='Chicken Liver'!C44 -> 0.27514795 | M28: ='Chicken Liver'!D40 -> 1.198143 | N28: ='Chicken Liver'!D41 -> 3.6 | O28: ='Chicken Liver'!D42 -> 0.3328175 | P28: =IF('Chicken Liver'!D43="","",'Chicken Liver'!D43) -> 4 | Q28: ='Chicken Liver'!D44 -> 0.29953575 | R28: ='Chicken Liver'!E40 -> 2.3895527 | S28: ='Chicken Liver'!E41 -> 6.8 | T28: ='Chicken Liver'!E42 -> 0.3514048 | U28: =IF('Chicken Liver'!E43="","",'Chicken Liver'!E43) -> 7.5 | V28: ='Chicken Liver'!E44 -> 0.31860702
A29: Qeema Meat | B29: Main dishes | H29: ='Qeema Meat'!C35 -> 0.51531775 | I29: ='Qeema Meat'!C36 -> 2.5 | J29: ='Qeema Meat'!C37 -> 0.2061271 | K29: =IF('Qeema Meat'!C38="","",'Qeema Meat'!C38) -> 2.5 | L29: ='Qeema Meat'!C39 -> 0.2061271 | M29: ='Qeema Meat'!D35 -> 1.0181275 | N29: ='Qeema Meat'!D36 -> 3.2 | O29: ='Qeema Meat'!D37 -> 0.31816484 | P29: =IF('Qeema Meat'!D38="","",'Qeema Meat'!D38) -> 3.5 | Q29: ='Qeema Meat'!D39 -> 0.29089357 | R29: ='Qeema Meat'!E35 -> 2.0635217 | S29: ='Qeema Meat'!E36 -> 5.4 | T29: ='Qeema Meat'!E37 -> 0.38213364 | U29: =IF('Qeema Meat'!E38="","",'Qeema Meat'!E38) -> 6 | V29: ='Qeema Meat'!E39 -> 0.34392028
A30: Nashif Chicken | B30: Main dishes | H30: ='Nashif Chicken'!C48 -> 0.42435552 | I30: ='Nashif Chicken'!C49 -> 1.8 | J30: ='Nashif Chicken'!C50 -> 0.23575307 | K30: =IF('Nashif Chicken'!C51="","",'Nashif Chicken'!C51) -> 2.2 | L30: ='Nashif Chicken'!C52 -> 0.19288887 | M30: ='Nashif Chicken'!D48 -> 0.82821105 | N30: ='Nashif Chicken'!D49 -> 3.4 | O30: ='Nashif Chicken'!D50 -> 0.24359148 | P30: =IF('Nashif Chicken'!D51="","",'Nashif Chicken'!D51) -> 4 | Q30: ='Nashif Chicken'!D52 -> 0.20705276 | R30: ='Nashif Chicken'!E48 -> 2.1702961 | S30: ='Nashif Chicken'!E49 -> 6.6 | T30: ='Nashif Chicken'!E50 -> 0.32883275 | U30: =IF('Nashif Chicken'!E51="","",'Nashif Chicken'!E51) -> 7.6 | V30: ='Nashif Chicken'!E52 -> 0.28556528
A31: Nashif Meat | B31: Main dishes | H31: ='Nashif Meat'!C42 -> 0.56822167 | I31: ='Nashif Meat'!C43 -> 2 | J31: ='Nashif Meat'!C44 -> 0.28411083 | K31: =IF('Nashif Meat'!C45="","",'Nashif Meat'!C45) -> 1.5 | L31: ='Nashif Meat'!C46 -> 0.37881444 | M31: ='Nashif Meat'!D42 -> 1.1167353 | N31: ='Nashif Meat'!D43 -> 3.8 | O31: ='Nashif Meat'!D44 -> 0.29387772 | P31: =IF('Nashif Meat'!D45="","",'Nashif Meat'!D45) -> 2.8 | Q31: ='Nashif Meat'!D46 -> 0.39883405 | R31: ='Nashif Meat'!E42 -> 2.2684173 | S31: ='Nashif Meat'!E43 -> 7 | T31: ='Nashif Meat'!E44 -> 0.32405962 | U31: =IF('Nashif Meat'!E45="","",'Nashif Meat'!E45) -> 5.4 | V31: ='Nashif Meat'!E46 -> 0.42007728
A32: Aseeda | B32: Sweets | C32: =Aseeda!C25 -> 0.0802147 | D32: =Aseeda!C26 -> 0.4 | E32: =Aseeda!C27 -> 0.20053675 | F32: =IF(Aseeda!C28="","",Aseeda!C28) -> 0.4 | G32: =Aseeda!C29 -> 0.20053675 | H32: =Aseeda!D25 -> 0.11849117 | I32: =Aseeda!D26 -> 0.7 | J32: =Aseeda!D27 -> 0.1692731 | K32: =IF(Aseeda!D28="","",Aseeda!D28) -> 1 | L32: =Aseeda!D29 -> 0.11849117 | M32: =Aseeda!E25 -> 0.17773675 | N32: =Aseeda!E26 -> 1 | O32: =Aseeda!E27 -> 0.17773675 | P32: =IF(Aseeda!E28="","",Aseeda!E28) -> 1.5 | Q32: =Aseeda!E29 -> 0.11849117 | R32: =Aseeda!F25 -> 0.37634017 | S32: =Aseeda!F26 -> 1.9 | T32: =Aseeda!F27 -> 0.19807377 | U32: =IF(Aseeda!F28="","",Aseeda!F28) -> 2.5 | V32: =Aseeda!F29 -> 0.15053607
A33: Qeemat | B33: Sweets | M33: =Qeemat!C25 -> 0.47186349 | N33: =Qeemat!C26 -> 1.4 | O33: =Qeemat!C27 -> 0.33704535 | P33: =IF(Qeemat!C28="","",Qeemat!C28) -> 1.8 | Q33: =Qeemat!C29 -> 0.26214638
A34: Balaleet | B34: Sweets | H34: =Balaleet!C25 -> 0.28695556 | I34: =Balaleet!C26 -> 1 | J34: =Balaleet!C27 -> 0.28695556 | K34: =IF(Balaleet!C28="","",Balaleet!C28) | L34: =Balaleet!C29 | M34: =Balaleet!D25 -> 0.43363333 | N34: =Balaleet!D26 -> 1.6 | O34: =Balaleet!D27 -> 0.27102083 | P34: =IF(Balaleet!D28="","",Balaleet!D28) -> 2 | Q34: =Balaleet!D29 -> 0.21681667 | R34: =Balaleet!E25 -> 0.89453333 | S34: =Balaleet!E26 -> 3 | T34: =Balaleet!E27 -> 0.29817778 | U34: =IF(Balaleet!E28="","",Balaleet!E28) | V34: =Balaleet!E29
A35: Fateeta | B35: Sweets | C35: =Fateeta!C24 -> 0.167105 | D35: =Fateeta!C25 -> 0.6 | E35: =Fateeta!C26 -> 0.27850833 | F35: =IF(Fateeta!C27="","",Fateeta!C27) -> 0.4 | G35: =Fateeta!C28 -> 0.4177625 | H35: =Fateeta!D24 -> 0.23337857 | I35: =Fateeta!D25 -> 0.9 | J35: =Fateeta!D26 -> 0.25930952 | K35: =IF(Fateeta!D27="","",Fateeta!D27) -> 1 | L35: =Fateeta!D28 -> 0.23337857 | M35: =Fateeta!E24 -> 0.3949625 | N35: =Fateeta!E25 -> 1.6 | O35: =Fateeta!E26 -> 0.24685156 | P35: =IF(Fateeta!E27="","",Fateeta!E27) -> 1.5 | Q35: =Fateeta!E28 -> 0.26330833 | R35: =Fateeta!F24 -> 0.81079167 | S35: =Fateeta!F25 -> 3 | T35: =Fateeta!F26 -> 0.27026389 | U35: =IF(Fateeta!F27="","",Fateeta!F27) -> 2.5 | V35: =Fateeta!F28 -> 0.32431667

Sheet LIST
A1: Sn | B1: Item | C1: Category | D1: Price (BHD) | E1: Pack qty | F1: Unit | G1: Unit price | H1: Previous price | I1: Market price
A2: 1 | B2: Bagal Leaves | C2: Vegetables | D2: 0.04 | E2: 50 | F2: g | G2: =IFERROR(D2/E2,0) -> 0.0008 | H2: 0.025 | I2: 0.025
A3: 2 | B3: Coriander Leaves | C3: Vegetables | D3: 0.095 | E3: 55 | F3: g | G3: =IFERROR(D3/E3,0) -> 0.0017272727 | H3: 0.08 | I3: 0.07
A4: 3 | B4: Curry Leaves | C4: Vegetables | D4: 1.95 | E4: 1000 | F4: g | G4: =IFERROR(D4/E4,0) -> 0.00195 | H4: 1.959 | I4: 1.087
A5: 4 | B5: Cabbage White | C5: Vegetables | D5: 0.4 | E5: 1000 | F5: g | G5: =IFERROR(D5/E5,0) -> 0.0004 | H5: 0.274 | I5: 0.23
A6: 5 | B6: Cauliflower | C6: Vegetables | D6: 0.65 | E6: 1000 | F6: g | G6: =IFERROR(D6/E6,0) -> 0.00065 | H6: 0.9 | I6: 0.375
A7: 6 | B7: Carrot | C7: Vegetables | D7: 0.85 | E7: 1000 | F7: g | G7: =IFERROR(D7/E7,0) -> 0.00085 | H7: 0.45 | I7: 0.45
A8: 7 | B8: Cucuamber | C8: Vegetables | D8: 0.45 | E8: 1000 | F8: g | G8: =IFERROR(D8/E8,0) -> 0.00045 | H8: 0.55 | I8: 0.35
A9: 8 | B9: Dill Leaves | C9: Vegetables | D9: 0.09 | E9: 60 | F9: g | G9: =IFERROR(D9/E9,0) -> 0.0015 | H9: 0.097 | I9: 0.08
A10: 9 | B10: Eggplant | C10: Vegetables | D10: 0.55 | E10: 1000 | F10: g | G10: =IFERROR(D10/E10,0) -> 0.00055 | H10: 0.58 | I10: 0.36
A11: 10 | B11: Garlic Peeled | C11: Vegetables | D11: 1.5 | E11: 1000 | F11: g | G11: =IFERROR(D11/E11,0) -> 0.0015 | H11: 1.4 | I11: 1.2
A12: 11 | B12: Green Capiscum | C12: Vegetables | D12: 0.65 | E12: 1000 | F12: g | G12: =IFERROR(D12/E12,0) -> 0.00065 | H12: 0.85 | I12: 0.571
A13: 12 | B13: Ginger + Garlic Mix | C13: Vegetables | D13: 1.2 | E13: 1000 | F13: g | G13: =IFERROR(D13/E13,0) -> 0.0012 | H13: 0.5 | I13: 0.5
... A29: 28 | B29: Chana Dal | C29: Beans & grains | D29: 0.581 | E29: 1000 | F29: g | G29: =IFERROR(D29/E29,0) -> 0.000581 | H29: 0.7 | I29: 0.433
A30: 29 | B30: Green lentils | C30: Beans & grains | D30: 0.4 | E30: 1000 | F30: g | G30: =IFERROR(D30/E30,0) -> 0.0004 | H30: 0.78
A31: 30 | B31: Harees | C31: Beans & grains | D31: 0.45 | E31: 1000 | F31: g | G31: =IFERROR(D31/E31,0) -> 0.00045 | H31: 0.5
A32: 31 | B32: Jareesh | C32: Beans & grains | D32: 0 | E32: 1000 | F32: g | G32: =IFERROR(D32/E32,0) -> 0 | H32: 0
A33: 32 | B33: Masoor Daal | C33: Beans & grains | D33: 0.454 | E33: 1000 | F33: g | G33: =IFERROR(D33/E33,0) -> 0.000454 | H33: 0.55 | I33: 0.433
A34: 33 | B34: Moong Dal | C34: Beans & grains | D34: 0.668 | E34: 1000 | F34: g | G34: =IFERROR(D34/E34,0) -> 0.000668 | H34: 0.74 | I34: 0.566
A35: 34 | B35: Rice 1121 | C35: Beans & grains | D35: 0.575 | E35: 1000 | F35: g | G35: =IFERROR(D35/E35,0) -> 0.000575 | H35: 0.525 | I35: 0.425
A36: 35 | B36: Raison | C36: Beans & grains | D36: 1.75 | E36: 1000 | F36: g | G36: =IFERROR(D36/E36,0) -> 0.00175 | H36: 1.65 | I36: 1.3
A37: 36 | B37: Rice Broken | C37: Beans & grains | D37: 0.3 | E37: 1000 | F37: g | G37: =IFERROR(D37/E37,0) -> 0.0003 | H37: 0.25
A38: 37 | B38: Sugar | C38: Beans & grains | D38: 0.3 | E38: 1000 | F38: g | G38: =IFERROR(D38/E38,0) -> 0.0003 | H38: 0.4
A39: 38 | B39: White Kidney Beans | C39: Beans & grains | D39: 0.818 | E39: 1000 | F39: g | G39: =IFERROR(D39/E39,0) -> 0.000818 | H39: 0.9 | I39: 0.766
A40: 39 | B40: Black Pepper Seeds | C40: Spices | D40: 4.09 | E40: 1000 | F40: g | G40: =IFERROR(D40/E40,0) -> 0.00409 | H40: 4.18
A41: 40 | B41: Black Pepper Powder | C41: Spices | D41: 2.272 | E41: 1000 | F41: g | G41: =IFERROR(D41/E41,0) -> 0.002272 | H41: 4.62
A42: 41 | B42: Black Lemone Powdre | C42: Spices | D42: 4.62 | E42: 1000 | F42: g | G42: =IFERROR(D42/E42,0) -> 0.00462 | H42: 0
A43: 42 | B43: Black Lemone Whole | C43: Spices | D43: 1.76 | E43: 1000 | F43: g | G43: =IFERROR(D43/E43,0) -> 0.00176 | H43: 1.6
A44: 43 | B44: Coriander Powder | C44: Spices | D44: 1.8 | E44: 1000 | F44: g | G44: =IFERROR(D44/E44,0) -> 0.0018 | H44: 1.3
A45: 44 | B45: Curry Powder | C45: Spices | D45: 1.65 | E45: 1000 | F45: g | G45: =IFERROR(D45/E45,0) -> 0.00165 | H45: 1.5
A46: 45 | B46: Cloves Seeds | C46: Spices | D46: 5.3636 | E46: 1000 | F46: g | G46: =IFERROR(D46/E46,0) -> 0.0053636 | H46: 6.5
A47: 46 | B47: Cummin Powder | C47: Spices | D47: 2.818 | E47: 1000 | F47: g | G47: =IFERROR(D47/E47,0) -> 0.002818 | H47: 3.1
A48: 47 | B48: Cummin Seeds | C48: Spices | D48: 2.8 | E48: 1000 | F48: g | G48: =IFERROR(D48/E48,0) -> 0.0028 | H48: 5.6
A49: 48 | B49: Cinamon Stick | C49: Spices | D49: 2.3636 | E49: 1000 | F49: g | G49: =IFERROR(D49/E49,0) -> 0.0023636 | H49: 2.6
A50: 49 | B50: Cinamon Powder | C50: Spices | D50: 2.6454 | E50: 1000 | F50: g | G50: =IFERROR(D50/E50,0) -> 0.0026454 | H50: 2.91
A51: 50 | B51: Cardmon Seeds | C51: Spices | D51: 16 | E51: 1000 | F51: g | G51: =IFERROR(D51/E51,0) -> 0.016 | H51: 15
... A63: 62 | B63: Tandori Masala Powder | C63: Spices | D63: 4 | E63: 1000 | F63: g | G63: =IFERROR(D63/E63,0) -> 0.004 | H63: 4.8
A64: 63 | B64: Beef Liver | C64: Frozen & meat | D64: 1.409 | E64: 1000 | F64: g | G64: =IFERROR(D64/E64,0) -> 0.001409 | H64: 1.21 | I64: 0.95
A65: 64 | B65: Beef Slice | C65: Frozen & meat | D65: 2.636 | E65: 900 | F65: g | G65: =IFERROR(D65/E65,0) -> 0.0029288889 | H65: 2.365 | I65: 1.833
A66: 65 | B66: Meat Boby Vel | C66: Frozen & meat | D66: 2.2 | E66: 1000 | F66: g | G66: =IFERROR(D66/E66,0) -> 0.0022 | H66: 2.2
...

Sheet Fool & Cheese
A1: Fool & Cheese
A2: Eggs & fool · one container takes several recipes · target 25%
A4: # | B4: Item | C4: Qty | D4: Unit | E4: Unit price | F4: Cost
A5: 1 | B5: Fool | C5: 190 | D5: =IFERROR(INDEX(LIST!$F$2:$F$131,MATCH(B5,LIST!$B$2:$B$131,0)),"") -> g | E5: =IFERROR(INDEX(LIST!$G$2:$G$131,MATCH(B5,LIST!$B$2:$B$131,0)),0) -> 0.0010177778 | F5: =C5*E5 -> 0.19337778
A6: 2 | B6: Cheddar Cheese | C6: 20 | D6: =IFERROR(INDEX(LIST!$F$2:$F$131,MATCH(B6,LIST!$B$2:$B$131,0)),"") -> g | E6: =IFERROR(INDEX(LIST!$G$2:$G$131,MATCH(B6,LIST!$B$2:$B$131,0)),0) -> 0.0021764706 | F6: =C6*E6 -> 0.043529412
A7: 3 | B7: Tahina | C7: 15 | D7: =IFERROR(INDEX(LIST!$F$2:$F$131,MATCH(B7,LIST!$B$2:$B$131,0)),"") -> g | E7: =IFERROR(INDEX(LIST!$G$2:$G$131,MATCH(B7,LIST!$B$2:$B$131,0)),0) -> 0.0009696 | F7: =C7*E7 -> 0.014544
A8: 4 | B8: Vegetable Oil | C8: 30 | D8: =IFERROR(INDEX(LIST!$F$2:$F$131,MATCH(B8,LIST!$B$2:$B$131,0)),"") -> ml | E8: =IFERROR(INDEX(LIST!$G$2:$G$131,MATCH(B8,LIST!$B$2:$B$131,0)),0) -> 0.000594 | F8: =C8*E8 -> 0.01782
A9: 5 | B9: Onion | C9: 60 | D9: =IFERROR(INDEX(LIST!$F$2:$F$131,MATCH(B9,LIST!$B$2:$B$131,0)),"") -> g | E9: =IFERROR(INDEX(LIST!$G$2:$G$131,MATCH(B9,LIST!$B$2:$B$131,0)),0) -> 0.00045 | F9: =C9*E9 -> 0.027
A10: 6 | B10: Tomato Paste | C10: 120 | D10: =IFERROR(INDEX(LIST!$F$2:$F$131,MATCH(B10,LIST!$B$2:$B$131,0)),"") -> g | E10: =IFERROR(INDEX(LIST!$G$2:$G$131,MATCH(B10,LIST!$B$2:$B$131,0)),0) -> 0.0006 | F10: =C10*E10 -> 0.072
A11: 7 | B11: Coriander Leaves | C11: 1 | D11: =IFERROR(INDEX(LIST!$F$2:$F$131,MATCH(B11,LIST!$B$2:$B$131,0)),"") -> g | E11: =IFERROR(INDEX(LIST!$G$2:$G$131,MATCH(B11,LIST!$B$2:$B$131,0)),0) -> 0.0017272727 | F11: =C11*E11 -> 0.0017272727
A12: 8 | B12: Green Capiscum | C12: 10 | D12: =IFERROR(INDEX(LIST!$F$2:$F$131,MATCH(B12,LIST!$B$2:$B$131,0)),"") -> g | E12: =IFERROR(INDEX(LIST!$G$2:$G$131,MATCH(B12,LIST!$B$2:$B$131,0)),0) -> 0.00065 | F12: =C12*E12 -> 0.0065
A13: 9 | B13: Mix Masala Powder | C13: 1.25 | D13: =IFERROR(INDEX(LIST!$F$2:$F$131,MATCH(B13,LIST!$B$2:$B$131,0)),"") -> g | E13: =IFERROR(INDEX(LIST!$G$2:$G$131,MATCH(B13,LIST!$B$2:$B$131,0)),0) -> 0.00165 | F13: =C13*E13 -> 0.0020625
A14: 10 | B14: Turmeric Powder | C14: 1.25 | D14: =IFERROR(INDEX(LIST!$F$2:$F$131,MATCH(B14,LIST!$B$2:$B$131,0)),"") -> g | E14: =IFERROR(INDEX(LIST!$G$2:$G$131,MATCH(B14,LIST!$B$2:$B$131,0)),0) -> 0.0018 | F14: =C14*E14 -> 0.00225
A15: 11 | B15: Cummin Powder | C15: 1.25 | D15: =IFERROR(INDEX(LIST!$F$2:$F$131,MATCH(B15,LIST!$B$2:$B$131,0)),"") -> g | E15: =IFERROR(INDEX(LIST!$G$2:$G$131,MATCH(B15,LIST!$B$2:$B$131,0)),0) -> 0.002818 | F15: =C15*E15 -> 0.0035225
A16: 12 | B16: Tandori Masala Powder | C16: 2.5 | D16: =IFERROR(INDEX(LIST!$F$2:$F$131,MATCH(B16,LIST!$B$2:$B$131,0)),"") -> g | E16: =IFERROR(INDEX(LIST!$G$2:$G$131,MATCH(B16,LIST!$B$2:$B$131,0)),0) -> 0.004 | F16: =C16*E16 -> 0.01
... A18: 14 | B18: Salt | C18: 2.5 | D18: =IFERROR(INDEX(LIST!$F$2:$F$131,MATCH(B18,LIST!$B$2:$B$131,0)),"") -> g | E18: =IFERROR(INDEX(LIST!$G$2:$G$131,MATCH(B18,LIST!$B$2:$B$131,0)),0) -> 0.000165 | F18: =C18*E18 -> 0.0004125
B19: TOTAL RECIPE COST | F19: =SUM(F5:F18) -> 0.39680846
B21: Size | C21: Small | D21: Medium | E21: Large
B22: Recipes per container | C22: 1 | D22: 2 | E22: 4
B23: Ingredient cost | C23: =$F$19*C22 -> 0.39680846 | D23: =$F$19*D22 -> 0.79361692 | E23: =$F$19*E22 -> 1.5872338
B24: Container | C24: CONTENER NO : (3) | D24: CONTENER NO : (4) | E24: CONTENER NO : (5)
B25: Container cost | C25: =IFERROR(INDEX(LIST!$G$2:$G$131,MATCH(C24,LIST!$B$2:$B$131,0)),0) -> 0.021 | D25: =IFERROR(INDEX(LIST!$G$2:$G$131,MATCH(D24,LIST!$B$2:$B$131,0)),0) -> 0.0315 | E25: =IFERROR(INDEX(LIST!$G$2:$G$131,MATCH(E24,LIST!$B$2:$B$131,0)),0) -> 0.11666667
B26: Spoons (qty) | C26: 1 | D26: 2 | E26: 3
B27: Spoon cost | C27: =C26*IFERROR(INDEX(LIST!$G$2:$G$131,MATCH("SPOON",LIST!$B$2:$B$131,0)),0) -> 0.0064 | D27: =D26*IFERROR(INDEX(LIST!$G$2:$G$131,MATCH("SPOON",LIST!$B$2:$B$131,0)),0) -> 0.0128 | E27: =E26*IFERROR(INDEX(LIST!$G$2:$G$131,MATCH("SPOON",LIST!$B$2:$B$131,0)),0) -> 0.0192
B28: Bread (qty) | C28: 1 | D28: 2 | E28: 4
B29: Bread cost | C29: =C28*IFERROR(INDEX(LIST!$G$2:$G$131,MATCH("Bread",LIST!$B$2:$B$131,0)),0) -> 0.012 | D29: =D28*IFERROR(INDEX(LIST!$G$2:$G$131,MATCH("Bread",LIST!$B$2:$B$131,0)),0) -> 0.024 | E29: =E28*IFERROR(INDEX(LIST!$G$2:$G$131,MATCH("Bread",LIST!$B$2:$B$131,0)),0) -> 0.048
B30: Bag | C30: Bag Small | D30: Bag Medium | E30: Bag Large
B31: Bag cost | C31: =IFERROR(INDEX(LIST!$G$2:$G$131,MATCH(C30,LIST!$B$2:$B$131,0)),0) -> 0.02 | D31: =IFERROR(INDEX(LIST!$G$2:$G$131,MATCH(D30,LIST!$B$2:$B$131,0)),0) -> 0.03 | E31: =IFERROR(INDEX(LIST!$G$2:$G$131,MATCH(E30,LIST!$B$2:$B$131,0)),0) -> 0.04
B32: Other costs | C32: 0 | D32: 0 | E32: 0
B33: Packaging total | C33: =C25+C27+C29+C31+C32 -> 0.0594 | D33: =D25+D27+D29+D31+D32 -> 0.0983 | E33: =E25+E27+E29+E31+E32 -> 0.22386667
B34: TOTAL COST | C34: =C23+C33 -> 0.45620846 | D34: =D23+D33 -> 0.89191692 | E34: =E23+E33 -> 1.8111005
B35: Store price | C35: 1.5 | D35: 2.8 | E35: 5.4
B36: Store cost % | C36: =IF(C35=0,"",C34/C35) -> 0.30413897 | D36: =IF(D35=0,"",D34/D35) -> 0.31854176 | E36: =IF(E35=0,"",E34/E35) -> 0.33538898
B37: Delivery price | C37: 1.9 | D37: 3.4 | E37: 6.4
B38: Delivery cost % | C38: =IF(N(C37)=0,"",C34/C37) -> 0.24010972 | D38: =IF(N(D37)=0,"",D34/D37) -> 0.26232851 | E38: =IF(N(E37)=0,"",E34/E37) -> 0.28298446
B39: Store profit | C39: =C35-C34 -> 1.0437915 | D39: =D35-D34 -> 1.9080831 | E39: =E35-E34 -> 3.5888995
B40: Delivery profit | C40: =IF(N(C37)=0,"",C37-C34) -> 1.4437915 | D40: =IF(N(D37)=0,"",D37-D34) -> 2.5080831 | E40: =IF(N(E37)=0,"",E37-E34) -> 4.5888995

Sheet Fasolya
A1: Fasolya
A2: Eggs & fool · one container takes several recipes · target 30%
A4: # | B4: Item | C4: Qty | D4: Unit | E4: Unit price | F4: Cost
A5: 1 | B5: Baked Beans | C5: 190 | D5: =IFERROR(INDEX(LIST!$F$2:$F$131,MATCH(B5,LIST!$B$2:$B$131,0)),"") -> g | E5: =IFERROR(INDEX(LIST!$G$2:$G$131,MATCH(B5,LIST!$B$2:$B$131,0)),0) -> 0.00094736842 | F5: =C5*E5 -> 0.18
A6: 2 | B6: Cheddar Cheese | C6: 10 | D6: =IFERROR(INDEX(LIST!$F$2:$F$131,MATCH(B6,LIST!$B$2:$B$131,0)),"") -> g | E6: =IFERROR(INDEX(LIST!$G$2:$G$131,MATCH(B6,LIST!$B$2:$B$131,0)),0) -> 0.0021764706 | F6: =C6*E6 -> 0.021764706
A7: 3 | B7: Tahina | C7: 15 | D7: =IFERROR(INDEX(LIST!$F$2:$F$131,MATCH(B7,LIST!$B$2:$B$131,0)),"") -> g | E7: =IFERROR(INDEX(LIST!$G$2:$G$131,MATCH(B7,LIST!$B$2:$B$131,0)),0) -> 0.0009696 | F7: =C7*E7 -> 0.014544
A8: 4 | B8: Vegetable Oil | C8: 30 | D8: =IFERROR(INDEX(LIST!$F$2:$F$131,MATCH(B8,LIST!$B$2:$B$131,0)),"") -> ml | E8: =IFERROR(INDEX(LIST!$G$2:$G$131,MATCH(B8,LIST!$B$2:$B$131,0)),0) -> 0.000594 | F8: =C8*E8 -> 0.01782
A9: 5 | B9: Onion | C9: 60 | D9: =IFERROR(INDEX(LIST!$F$2:$F$131,MATCH(B9,LIST!$B$2:$B$131,0)),"") -> g | E9: =IFERROR(INDEX(LIST!$G$2:$G$131,MATCH(B9,LIST!$B$2:$B$131,0)),0) -> 0.00045 | F9: =C9*E9 -> 0.027
A10: 6 | B10: Tomato | C10: 120 | D10: =IFERROR(INDEX(LIST!$F$2:$F$131,MATCH(B10,LIST!$B$2:$B$131,0)),"") -> g | E10: =IFERROR(INDEX(LIST!$G$2:$G$131,MATCH(B10,LIST!$B$2:$B$131,0)),0) -> 0.0005 | F10: =C10*E10 -> 0.06
A11: 7 | B11: Coriander Leaves | C11: 1 | D11: =IFERROR(INDEX(LIST!$F$2:$F$131,MATCH(B11,LIST!$B$2:$B$131,0)),"") -> g | E11: =IFERROR(INDEX(LIST!$G$2:$G$131,MATCH(B11,LIST!$B$2:$B$131,0)),0) -> 0.0017272727 | F11: =C11*E11 -> 0.0017272727
A12: 8 | B12: Green Capiscum | C12: 10 | D12: =IFERROR(INDEX(LIST!$F$2:$F$131,MATCH(B12,LIST!$B$2:$B$131,0)),"") -> g | E12: =IFERROR(INDEX(LIST!$G$2:$G$131,MATCH(B12,LIST!$B$2:$B$131,0)),0) -> 0.00065 | F12: =C12*E12 -> 0.0065
A13: 9 | B13: Mix Masala Powder | C13: 1.25 | D13: =IFERROR(INDEX(LIST!$F$2:$F$131,MATCH(B13,LIST!$B$2:$B$131,0)),"") -> g | E13: =IFERROR(INDEX(LIST!$G$2:$G$131,MATCH(B13,LIST!$B$2:$B$131,0)),0) -> 0.00165 | F13: =C13*E13 -> 0.0020625
A14: 10 | B14: Turmeric Powder | C14: 1.25 | D14: =IFERROR(INDEX(LIST!$F$2:$F$131,MATCH(B14,LIST!$B$2:$B$131,0)),"") -> g | E14: =IFERROR(INDEX(LIST!$G$2:$G$131,MATCH(B14,LIST!$B$2:$B$131,0)),0) -> 0.0018 | F14: =C14*E14 -> 0.00225
A15: 11 | B15: Cummin Powder | C15: 1.25 | D15: =IFERROR(INDEX(LIST!$F$2:$F$131,MATCH(B15,LIST!$B$2:$B$131,0)),"") -> g | E15: =IFERROR(INDEX(LIST!$G$2:$G$131,MATCH(B15,LIST!$B$2:$B$131,0)),0) -> 0.002818 | F15: =C15*E15 -> 0.0035225
A16: 12 | B16: Tandori Masala Powder | C16: 2.5 | D16: =IFERROR(INDEX(LIST!$F$2:$F$131,MATCH(B16,LIST!$B$2:$B$131,0)),"") -> g | E16: =IFERROR(INDEX(LIST!$G$2:$G$131,MATCH(B16,LIST!$B$2:$B$131,0)),0) -> 0.004 | F16: =C16*E16 -> 0.01
... A18: 14 | B18: Salt | C18: 2.5 | D18: =IFERROR(INDEX(LIST!$F$2:$F$131,MATCH(B18,LIST!$B$2:$B$131,0)),"") -> g | E18: =IFERROR(INDEX(LIST!$G$2:$G$131,MATCH(B18,LIST!$B$2:$B$131,0)),0) -> 0.000165 | F18: =C18*E18 -> 0.0004125
B19: TOTAL RECIPE COST | F19: =SUM(F5:F18) -> 0.34966598
B21: Size | C21: Small | D21: Medium | E21: Large
B22: Recipes per container | C22: 1 | D22: 2 | E22: 4
B23: Ingredient cost | C23: =$F$19*C22 -> 0.34966598 | D23: =$F$19*D22 -> 0.69933196 | E23: =$F$19*E22 -> 1.3986639
B24: Container | C24: CONTENER NO : (3) | D24: CONTENER NO : (4) | E24: CONTENER NO : (5)
B25: Container cost | C25: =IFERROR(INDEX(LIST!$G$2:$G$131,MATCH(C24,LIST!$B$2:$B$131,0)),0) -> 0.021 | D25: =IFERROR(INDEX(LIST!$G$2:$G$131,MATCH(D24,LIST!$B$2:$B$131,0)),0) -> 0.0315 | E25: =IFERROR(INDEX(LIST!$G$2:$G$131,MATCH(E24,LIST!$B$2:$B$131,0)),0) -> 0.11666667
B26: Spoons (qty) | C26: 1 | D26: 2 | E26: 3
B27: Spoon cost | C27: =C26*IFERROR(INDEX(LIST!$G$2:$G$131,MATCH("SPOON",LIST!$B$2:$B$131,0)),0) -> 0.0064 | D27: =D26*IFERROR(INDEX(LIST!$G$2:$G$131,MATCH("SPOON",LIST!$B$2:$B$131,0)),0) -> 0.0128 | E27: =E26*IFERROR(INDEX(LIST!$G$2:$G$131,MATCH("SPOON",LIST!$B$2:$B$131,0)),0) -> 0.0192
B28: Bread (qty) | C28: 1 | D28: 2 | E28: 4
B29: Bread cost | C29: =C28*IFERROR(INDEX(LIST!$G$2:$G$131,MATCH("Bread",LIST!$B$2:$B$131,0)),0) -> 0.012 | D29: =D28*IFERROR(INDEX(LIST!$G$2:$G$131,MATCH("Bread",LIST!$B$2:$B$131,0)),0) -> 0.024 | E29: =E28*IFERROR(INDEX(LIST!$G$2:$G$131,MATCH("Bread",LIST!$B$2:$B$131,0)),0) -> 0.048
B30: Bag | C30: Bag Small | D30: Bag Medium | E30: Bag Large
B31: Bag cost | C31: =IFERROR(INDEX(LIST!$G$2:$G$131,MATCH(C30,LIST!$B$2:$B$131,0)),0) -> 0.02 | D31: =IFERROR(INDEX(LIST!$G$2:$G$131,MATCH(D30,LIST!$B$2:$B$131,0)),0) -> 0.03 | E31: =IFERROR(INDEX(LIST!$G$2:$G$131,MATCH(E30,LIST!$B$2:$B$131,0)),0) -> 0.04
B32: Other costs | C32: 0 | D32: 0 | E32: 0
B33: Packaging total | C33: =C25+C27+C29+C31+C32 -> 0.0594 | D33: =D25+D27+D29+D31+D32 -> 0.0983 | E33: =E25+E27+E29+E31+E32 -> 0.22386667
B34: TOTAL COST | C34: =C23+C33 -> 0.40906598 | D34: =D23+D33 -> 0.79763196 | E34: =E23+E33 -> 1.6225306
B35: Store price | C35: 1.3 | D35: 2.4 | E35: 4.6
B36: Store cost % | C36: =IF(C35=0,"",C34/C35) -> 0.31466614 | D36: =IF(D35=0,"",D34/D35) -> 0.33234665 | E36: =IF(E35=0,"",E34/E35) -> 0.35272404
B37: Delivery price | C37: 1.7 | D37: 3 | E37: 5.6
B38: Delivery cost % | C38: =IF(N(C37)=0,"",C34/C37) -> 0.24062705 | D38: =IF(N(D37)=0,"",D34/D37) -> 0.26587732 | E38: =IF(N(E37)=0,"",E34/E37) -> 0.2897376
B39: Store profit | C39: =C35-C34 -> 0.89093402 | D39: =D35-D34 -> 1.602368 | E39: =E35-E34 -> 2.9774694
B40: Delivery profit | C40: =IF(N(C37)=0,"",C37-C34) -> 1.290934 | D40: =IF(N(D37)=0,"",D37-D34) -> 2.202368 | E40: =IF(N(E37)=0,"",E37-E34) -> 3.9774694

Sheet S.Egg Bin Aqool
A1: S.Egg Bin Aqool
A2: Eggs & fool · one container takes several recipes · target 30%
A4: # | B4: Item | C4: Qty | D4: Unit | E4: Unit price | F4: Cost
A5: 1 | B5: Green Peas (S.P) | C5: 190 | D5: =IFERROR(INDEX(LIST!$F$2:$F$131,MATCH(B5,LIST!$B$2:$B$131,0)),"") -> g | E5: =IFERROR(INDEX(LIST!$G$2:$G$131,MATCH(B5,LIST!$B$2:$B$131,0)),0) -> 0.00077105263 | F5: =C5*E5 -> 0.1465
A6: 2 | B6: Egg | C6: 2 | D6: =IFERROR(INDEX(LIST!$F$2:$F$131,MATCH(B6,LIST!$B$2:$B$131,0)),"") -> pc | E6: =IFERROR(INDEX(LIST!$G$2:$G$131,MATCH(B6,LIST!$B$2:$B$131,0)),0) -> 0.035 | F6: =C6*E6 -> 0.07
A7: 3 | B7: Cheddar Cheese | C7: 10 | D7: =IFERROR(INDEX(LIST!$F$2:$F$131,MATCH(B7,LIST!$B$2:$B$131,0)),"") -> g | E7: =IFERROR(INDEX(LIST!$G$2:$G$131,MATCH(B7,LIST!$B$2:$B$131,0)),0) -> 0.0021764706 | F7: =C7*E7 -> 0.021764706
A8: 4 | B8: Onion | C8: 60 | D8: =IFERROR(INDEX(LIST!$F$2:$F$131,MATCH(B8,LIST!$B$2:$B$131,0)),"") -> g | E8: =IFERROR(INDEX(LIST!$G$2:$G$131,MATCH(B8,LIST!$B$2:$B$131,0)),0) -> 0.00045 | F8: =C8*E8 -> 0.027
A9: 5 | B9: Long Chilly | C9: 7.5 | D9: =IFERROR(INDEX(LIST!$F$2:$F$131,MATCH(B9,LIST!$B$2:$B$131,0)),"") -> g | E9: =IFERROR(INDEX(LIST!$G$2:$G$131,MATCH(B9,LIST!$B$2:$B$131,0)),0) -> 0.0011 | F9: =C9*E9 -> 0.00825
A10: 6 | B10: Tomato | C10: 80 | D10: =IFERROR(INDEX(LIST!$F$2:$F$131,MATCH(B10,LIST!$B$2:$B$131,0)),"") -> g | E10: =IFERROR(INDEX(LIST!$G$2:$G$131,MATCH(B10,LIST!$B$2:$B$131,0)),0) -> 0.0005 | F10: =C10*E10 -> 0.04
A11: 7 | B11: Potato | C11: 7.5 | D11: =IFERROR(INDEX(LIST!$F$2:$F$131,MATCH(B11,LIST!$B$2:$B$131,0)),"") -> g | E11: =IFERROR(INDEX(LIST!$G$2:$G$131,MATCH(B11,LIST!$B$2:$B$131,0)),0) -> 0.00036 | F11: =C11*E11 -> 0.0027
A12: 8 | B12: Green Capiscum | C12: 15 | D12: =IFERROR(INDEX(LIST!$F$2:$F$131,MATCH(B12,LIST!$B$2:$B$131,0)),"") -> g | E12: =IFERROR(INDEX(LIST!$G$2:$G$131,MATCH(B12,LIST!$B$2:$B$131,0)),0) -> 0.00065 | F12: =C12*E12 -> 0.00975
A13: 9 | B13: Vegetable Oil | C13: 30 | D13: =IFERROR(INDEX(LIST!$F$2:$F$131,MATCH(B13,LIST!$B$2:$B$131,0)),"") -> ml | E13: =IFERROR(INDEX(LIST!$G$2:$G$131,MATCH(B13,LIST!$B$2:$B$131,0)),0) -> 0.000594 | F13: =C13*E13 -> 0.01782
A14: 10 | B14: Tomato Paste | C14: 10 | D14: =IFERROR(INDEX(LIST!$F$2:$F$131,MATCH(B14,LIST!$B$2:$B$131,0)),"") -> g | E14: =IFERROR(INDEX(LIST!$G$2:$G$131,MATCH(B14,LIST!$B$2:$B$131,0)),0) -> 0.0006 | F14: =C14*E14 -> 0.006
A15: 11 | B15: Salt | C15: 2.5 | D15: =IFERROR(INDEX(LIST!$F$2:$F$131,MATCH(B15,LIST!$B$2:$B$131,0)),"") -> g | E15: =IFERROR(INDEX(LIST!$G$2:$G$131,MATCH(B15,LIST!$B$2:$B$131,0)),0) -> 0.000165 | F15: =C15*E15 -> 0.0004125
A16: 12 | B16: Olive Oil | C16: 7.5 | D16: =IFERROR(INDEX(LIST!$F$2:$F$131,MATCH(B16,LIST!$B$2:$B$131,0)),"") -> ml | E16: =IFERROR(INDEX(LIST!$G$2:$G$131,MATCH(B16,LIST!$B$2:$B$131,0)),0) -> 0.000308 | F16: =C16*E16 -> 0.00231
... A21: 17 | B21: Mix Masala Powder | C21: 1.25 | D21: =IFERROR(INDEX(LIST!$F$2:$F$131,MATCH(B21,LIST!$B$2:$B$131,0)),"") -> g | E21: =IFERROR(INDEX(LIST!$G$2:$G$131,MATCH(B21,LIST!$B$2:$B$131,0)),0) -> 0.00165 | F21: =C21*E21 -> 0.0020625
B22: TOTAL RECIPE COST | F22: =SUM(F5:F21) -> 0.37969871
B24: Size | C24: Small | D24: Medium | E24: Large
B25: Recipes per container | C25: 1 | D25: 2 | E25: 4
B26: Ingredient cost | C26: =$F$22*C25 -> 0.37969871 | D26: =$F$22*D25 -> 0.75939741 | E26: =$F$22*E25 -> 1.5187948
B27: Container | C27: CONTENER NO : (3) | D27: CONTENER NO : (4) | E27: CONTENER NO : (5)
B28: Container cost | C28: =IFERROR(INDEX(LIST!$G$2:$G$131,MATCH(C27,LIST!$B$2:$B$131,0)),0) -> 0.021 | D28: =IFERROR(INDEX(LIST!$G$2:$G$131,MATCH(D27,LIST!$B$2:$B$131,0)),0) -> 0.0315 | E28: =IFERROR(INDEX(LIST!$G$2:$G$131,MATCH(E27,LIST!$B$2:$B$131,0)),0) -> 0.11666667
B29: Spoons (qty) | C29: 1 | D29: 2 | E29: 3
B30: Spoon cost | C30: =C29*IFERROR(INDEX(LIST!$G$2:$G$131,MATCH("SPOON",LIST!$B$2:$B$131,0)),0) -> 0.0064 | D30: =D29*IFERROR(INDEX(LIST!$G$2:$G$131,MATCH("SPOON",LIST!$B$2:$B$131,0)),0) -> 0.0128 | E30: =E29*IFERROR(INDEX(LIST!$G$2:$G$131,MATCH("SPOON",LIST!$B$2:$B$131,0)),0) -> 0.0192
B31: Bread (qty) | C31: 1 | D31: 2 | E31: 4
B32: Bread cost | C32: =C31*IFERROR(INDEX(LIST!$G$2:$G$131,MATCH("Bread",LIST!$B$2:$B$131,0)),0) -> 0.012 | D32: =D31*IFERROR(INDEX(LIST!$G$2:$G$131,MATCH("Bread",LIST!$B$2:$B$131,0)),0) -> 0.024 | E32: =E31*IFERROR(INDEX(LIST!$G$2:$G$131,MATCH("Bread",LIST!$B$2:$B$131,0)),0) -> 0.048
B33: Bag | C33: Bag Small | D33: Bag Medium | E33: Bag Large
B34: Bag cost | C34: =IFERROR(INDEX(LIST!$G$2:$G$131,MATCH(C33,LIST!$B$2:$B$131,0)),0) -> 0.02 | D34: =IFERROR(INDEX(LIST!$G$2:$G$131,MATCH(D33,LIST!$B$2:$B$131,0)),0) -> 0.03 | E34: =IFERROR(INDEX(LIST!$G$2:$G$131,MATCH(E33,LIST!$B$2:$B$131,0)),0) -> 0.04
B35: Other costs | C35: 0 | D35: 0 | E35: 0
B36: Packaging total | C36: =C28+C30+C32+C34+C35 -> 0.0594 | D36: =D28+D30+D32+D34+D35 -> 0.0983 | E36: =E28+E30+E32+E34+E35 -> 0.22386667
B37: TOTAL COST | C37: =C26+C36 -> 0.43909871 | D37: =D26+D36 -> 0.85769741 | E37: =E26+E36 -> 1.7426615
B38: Store price | C38: 1.6 | D38: 3 | E38: 5.6
B39: Store cost % | C39: =IF(C38=0,"",C37/C38) -> 0.27443669 | D39: =IF(D38=0,"",D37/D38) -> 0.28589914 | E39: =IF(E38=0,"",E37/E38) -> 0.31118955
B40: Delivery price | C40: 2 | D40: 3.6 | E40: 6.8
B41: Delivery cost % | C41: =IF(N(C40)=0,"",C37/C40) -> 0.21954935 | D41: =IF(N(D40)=0,"",D37/D40) -> 0.23824928 | E41: =IF(N(E40)=0,"",E37/E40) -> 0.25627375
B42: Store profit | C42: =C38-C37 -> 1.1609013 | D42: =D38-D37 -> 2.1423026 | E42: =E38-E37 -> 3.8573385
B43: Delivery profit | C43: =IF(N(C40)=0,"",C40-C37) -> 1.5609013 | D43: =IF(N(D40)=0,"",D40-D37) -> 2.7423026 | E43: =IF(N(E40)=0,"",E40-E37) -> 5.0573385

Sheet Egg Shakshoka
A1: Egg Shakshoka
A2: Eggs & fool · one container takes several recipes · target 30%
A4: # | B4: Item | C4: Qty | D4: Unit | E4: Unit price | F4: Cost
A5: 1 | B5: Egg | C5: 2 | D5: =IFERROR(INDEX(LIST!$F$2:$F$131,MATCH(B5,LIST!$B$2:$B$131,0)),"") -> pc | E5: =IFERROR(INDEX(LIST!$G$2:$G$131,MATCH(B5,LIST!$B$2:$B$131,0)),0) -> 0.035 | F5: =C5*E5 -> 0.07
A6: 2 | B6: Vegetable Oil | C6: 30 | D6: =IFERROR(INDEX(LIST!$F$2:$F$131,MATCH(B6,LIST!$B$2:$B$131,0)),"") -> ml | E6: =IFERROR(INDEX(LIST!$G$2:$G$131,MATCH(B6,LIST!$B$2:$B$131,0)),0) -> 0.000594 | F6: =C6*E6 -> 0.01782
A7: 3 | B7: Tomato Paste | C7: 10 | D7: =IFERROR(INDEX(LIST!$F$2:$F$131,MATCH(B7,LIST!$B$2:$B$131,0)),"") -> g | E7: =IFERROR(INDEX(LIST!$G$2:$G$131,MATCH(B7,LIST!$B$2:$B$131,0)),0) -> 0.0006 | F7: =C7*E7 -> 0.006
A8: 4 | B8: Onion | C8: 60 | D8: =IFERROR(INDEX(LIST!$F$2:$F$131,MATCH(B8,LIST!$B$2:$B$131,0)),"") -> g | E8: =IFERROR(INDEX(LIST!$G$2:$G$131,MATCH(B8,LIST!$B$2:$B$131,0)),0) -> 0.00045 | F8: =C8*E8 -> 0.027
A9: 5 | B9: Coriander Leaves | C9: 2 | D9: =IFERROR(INDEX(LIST!$F$2:$F$131,MATCH(B9,LIST!$B$2:$B$131,0)),"") -> g | E9: =IFERROR(INDEX(LIST!$G$2:$G$131,MATCH(B9,LIST!$B$2:$B$131,0)),0) -> 0.0017272727 | F9: =C9*E9 -> 0.0034545455
A10: 6 | B10: Tomato | C10: 120 | D10: =IFERROR(INDEX(LIST!$F$2:$F$131,MATCH(B10,LIST!$B$2:$B$131,0)),"") -> g | E10: =IFERROR(INDEX(LIST!$G$2:$G$131,MATCH(B10,LIST!$B$2:$B$131,0)),0) -> 0.0005 | F10: =C10*E10 -> 0.06
A11: 7 | B11: Turmeric Powder | C11: 1.25 | D11: =IFERROR(INDEX(LIST!$F$2:$F$131,MATCH(B11,LIST!$B$2:$B$131,0)),"") -> g | E11: =IFERROR(INDEX(LIST!$G$2:$G$131,MATCH(B11,LIST!$B$2:$B$131,0)),0) -> 0.0018 | F11: =C11*E11 -> 0.00225
A12: 8 | B12: Cummin Powder | C12: 1.25 | D12: =IFERROR(INDEX(LIST!$F$2:$F$131,MATCH(B12,LIST!$B$2:$B$131,0)),"") -> g | E12: =IFERROR(INDEX(LIST!$G$2:$G$131,MATCH(B12,LIST!$B$2:$B$131,0)),0) -> 0.002818 | F12: =C12*E12 -> 0.0035225
A13: 9 | B13: Tandori Masala Powder | C13: 1.25 | D13: =IFERROR(INDEX(LIST!$F$2:$F$131,MATCH(B13,LIST!$B$2:$B$131,0)),"") -> g | E13: =IFERROR(INDEX(LIST!$G$2:$G$131,MATCH(B13,LIST!$B$2:$B$131,0)),0) -> 0.004 | F13: =C13*E13 -> 0.005
A14: 10 | B14: Curry Powder | C14: 1.25 | D14: =IFERROR(INDEX(LIST!$F$2:$F$131,MATCH(B14,LIST!$B$2:$B$131,0)),"") -> g | E14: =IFERROR(INDEX(LIST!$G$2:$G$131,MATCH(B14,LIST!$B$2:$B$131,0)),0) -> 0.00165 | F14: =C14*E14 -> 0.0020625
A15: 11 | B15: Salt | C15: 1.25 | D15: =IFERROR(INDEX(LIST!$F$2:$F$131,MATCH(B15,LIST!$B$2:$B$131,0)),"") -> g | E15: =IFERROR(INDEX(LIST!$G$2:$G$131,MATCH(B15,LIST!$B$2:$B$131,0)),0) -> 0.000165 | F15: =C15*E15 -> 0.00020625
B16: TOTAL RECIPE COST | F16: =SUM(F5:F15) -> 0.1973158
B18: Size | C18: Small | D18: Medium | E18: Large
B19: Recipes per container | C19: 1 | D19: 2 | E19: 4
B20: Ingredient cost | C20: =$F$16*C19 -> 0.1973158 | D20: =$F$16*D19 -> 0.39463159 | E20: =$F$16*E19 -> 0.78926318
B21: Container | C21: CONTENER NO : (3) | D21: CONTENER NO : (4) | E21: CONTENER NO : (5)
B22: Container cost | C22: =IFERROR(INDEX(LIST!$G$2:$G$131,MATCH(C21,LIST!$B$2:$B$131,0)),0) -> 0.021 | D22: =IFERROR(INDEX(LIST!$G$2:$G$131,MATCH(D21,LIST!$B$2:$B$131,0)),0) -> 0.0315 | E22: =IFERROR(INDEX(LIST!$G$2:$G$131,MATCH(E21,LIST!$B$2:$B$131,0)),0) -> 0.11666667
B23: Spoons (qty) | C23: 1 | D23: 2 | E23: 3
B24: Spoon cost | C24: =C23*IFERROR(INDEX(LIST!$G$2:$G$131,MATCH("SPOON",LIST!$B$2:$B$131,0)),0) -> 0.0064 | D24: =D23*IFERROR(INDEX(LIST!$G$2:$G$131,MATCH("SPOON",LIST!$B$2:$B$131,0)),0) -> 0.0128 | E24: =E23*IFERROR(INDEX(LIST!$G$2:$G$131,MATCH("SPOON",LIST!$B$2:$B$131,0)),0) -> 0.0192
B25: Bread (qty) | C25: 1 | D25: 2 | E25: 4
B26: Bread cost | C26: =C25*IFERROR(INDEX(LIST!$G$2:$G$131,MATCH("Bread",LIST!$B$2:$B$131,0)),0) -> 0.012 | D26: =D25*IFERROR(INDEX(LIST!$G$2:$G$131,MATCH("Bread",LIST!$B$2:$B$131,0)),0) -> 0.024 | E26: =E25*IFERROR(INDEX(LIST!$G$2:$G$131,MATCH("Bread",LIST!$B$2:$B$131,0)),0) -> 0.048
B27: Bag | C27: Bag Small | D27: Bag Medium | E27: Bag Large
B28: Bag cost | C28: =IFERROR(INDEX(LIST!$G$2:$G$131,MATCH(C27,LIST!$B$2:$B$131,0)),0) -> 0.02 | D28: =IFERROR(INDEX(LIST!$G$2:$G$131,MATCH(D27,LIST!$B$2:$B$131,0)),0) -> 0.03 | E28: =IFERROR(INDEX(LIST!$G$2:$G$131,MATCH(E27,LIST!$B$2:$B$131,0)),0) -> 0.04
B29: Other costs | C29: 0 | D29: 0 | E29: 0
B30: Packaging total | C30: =C22+C24+C26+C28+C29 -> 0.0594 | D30: =D22+D24+D26+D28+D29 -> 0.0983 | E30: =E22+E24+E26+E28+E29 -> 0.22386667
B31: TOTAL COST | C31: =C20+C30 -> 0.2567158 | D31: =D20+D30 -> 0.49293159 | E31: =E20+E30 -> 1.0131298
B32: Store price | C32: 1.2 | D32: 2.2 | E32: 4.2
B33: Store cost % | C33: =IF(C32=0,"",C31/C32) -> 0.21392983 | D33: =IF(D32=0,"",D31/D32) -> 0.22405981 | E33: =IF(E32=0,"",E31/E32) -> 0.24122139
B34: Delivery price | C34: 1.6 | D34: 2.8 | E34: 5
B35: Delivery cost % | C35: =IF(N(C34)=0,"",C31/C34) -> 0.16044737 | D35: =IF(N(D34)=0,"",D31/D34) -> 0.176047 | E35: =IF(N(E34)=0,"",E31/E34) -> 0.20262597
B36: Store profit | C36: =C32-C31 -> 0.9432842 | D36: =D32-D31 -> 1.7070684 | E36: =E32-E31 -> 3.1868702
B37: Delivery profit | C37: =IF(N(C34)=0,"",C34-C31) -> 1.3432842 | D37: =IF(N(D34)=0,"",D34-D31) -> 2.3070684 | E37: =IF(N(E34)=0,"",E34-E31) -> 3.9868702

Sheet Egg Vegatable
A1: Egg Vegatable
A2: Eggs & fool · one container takes several recipes · target 30%
A4: # | B4: Item | C4: Qty | D4: Unit | E4: Unit price | F4: Cost
A5: 1 | B5: Egg | C5: 2 | D5: =IFERROR(INDEX(LIST!$F$2:$F$131,MATCH(B5,LIST!$B$2:$B$131,0)),"") -> pc | E5: =IFERROR(INDEX(LIST!$G$2:$G$131,MATCH(B5,LIST!$B$2:$B$131,0)),0) -> 0.035 | F5: =C5*E5 -> 0.07
A6: 2 | B6: Vegetable Oil | C6: 15 | D6: =IFERROR(INDEX(LIST!$F$2:$F$131,MATCH(B6,LIST!$B$2:$B$131,0)),"") -> ml | E6: =IFERROR(INDEX(LIST!$G$2:$G$131,MATCH(B6,LIST!$B$2:$B$131,0)),0) -> 0.000594 | F6: =C6*E6 -> 0.00891
A7: 3 | B7: Tomato Paste | C7: 15 | D7: =IFERROR(INDEX(LIST!$F$2:$F$131,MATCH(B7,LIST!$B$2:$B$131,0)),"") -> g | E7: =IFERROR(INDEX(LIST!$G$2:$G$131,MATCH(B7,LIST!$B$2:$B$131,0)),0) -> 0.0006 | F7: =C7*E7 -> 0.009
A8: 4 | B8: Onion | C8: 60 | D8: =IFERROR(INDEX(LIST!$F$2:$F$131,MATCH(B8,LIST!$B$2:$B$131,0)),"") -> g | E8: =IFERROR(INDEX(LIST!$G$2:$G$131,MATCH(B8,LIST!$B$2:$B$131,0)),0) -> 0.00045 | F8: =C8*E8 -> 0.027
A9: 5 | B9: Potato | C9: 30 | D9: =IFERROR(INDEX(LIST!$F$2:$F$131,MATCH(B9,LIST!$B$2:$B$131,0)),"") -> g | E9: =IFERROR(INDEX(LIST!$G$2:$G$131,MATCH(B9,LIST!$B$2:$B$131,0)),0) -> 0.00036 | F9: =C9*E9 -> 0.0108
A10: 6 | B10: Green Capiscum | C10: 15 | D10: =IFERROR(INDEX(LIST!$F$2:$F$131,MATCH(B10,LIST!$B$2:$B$131,0)),"") -> g | E10: =IFERROR(INDEX(LIST!$G$2:$G$131,MATCH(B10,LIST!$B$2:$B$131,0)),0) -> 0.00065 | F10: =C10*E10 -> 0.00975
A11: 7 | B11: Coriander Leaves | C11: 2 | D11: =IFERROR(INDEX(LIST!$F$2:$F$131,MATCH(B11,LIST!$B$2:$B$131,0)),"") -> g | E11: =IFERROR(INDEX(LIST!$G$2:$G$131,MATCH(B11,LIST!$B$2:$B$131,0)),0) -> 0.0017272727 | F11: =C11*E11 -> 0.0034545455
A12: 8 | B12: Tomato | C12: 120 | D12: =IFERROR(INDEX(LIST!$F$2:$F$131,MATCH(B12,LIST!$B$2:$B$131,0)),"") -> g | E12: =IFERROR(INDEX(LIST!$G$2:$G$131,MATCH(B12,LIST!$B$2:$B$131,0)),0) -> 0.0005 | F12: =C12*E12 -> 0.06
A13: 9 | B13: Mix Masala Powder | C13: 1.2 | D13: =IFERROR(INDEX(LIST!$F$2:$F$131,MATCH(B13,LIST!$B$2:$B$131,0)),"") -> g | E13: =IFERROR(INDEX(LIST!$G$2:$G$131,MATCH(B13,LIST!$B$2:$B$131,0)),0) -> 0.00165 | F13: =C13*E13 -> 0.00198
A14: 10 | B14: Cummin Powder | C14: 1.2 | D14: =IFERROR(INDEX(LIST!$F$2:$F$131,MATCH(B14,LIST!$B$2:$B$131,0)),"") -> g | E14: =IFERROR(INDEX(LIST!$G$2:$G$131,MATCH(B14,LIST!$B$2:$B$131,0)),0) -> 0.002818 | F14: =C14*E14 -> 0.0033816
A15: 11 | B15: Tandori Masala Powder | C15: 1.2 | D15: =IFERROR(INDEX(LIST!$F$2:$F$131,MATCH(B15,LIST!$B$2:$B$131,0)),"") -> g | E15: =IFERROR(INDEX(LIST!$G$2:$G$131,MATCH(B15,LIST!$B$2:$B$131,0)),0) -> 0.004 | F15: =C15*E15 -> 0.0048
A16: 12 | B16: Turmeric Powder | C16: 1.2 | D16: =IFERROR(INDEX(LIST!$F$2:$F$131,MATCH(B16,LIST!$B$2:$B$131,0)),"") -> g | E16: =IFERROR(INDEX(LIST!$G$2:$G$131,MATCH(B16,LIST!$B$2:$B$131,0)),0) -> 0.0018 | F16: =C16*E16 -> 0.00216
... A18: 14 | B18: Salt | C18: 2.5 | D18: =IFERROR(INDEX(LIST!$F$2:$F$131,MATCH(B18,LIST!$B$2:$B$131,0)),"") -> g | E18: =IFERROR(INDEX(LIST!$G$2:$G$131,MATCH(B18,LIST!$B$2:$B$131,0)),0) -> 0.000165 | F18: =C18*E18 -> 0.0004125
B19: TOTAL RECIPE COST | F19: =SUM(F5:F18) -> 0.21362865
B21: Size | C21: Small | D21: Medium | E21: Large
B22: Recipes per container | C22: 1 | D22: 2 | E22: 4
B23: Ingredient cost | C23: =$F$19*C22 -> 0.21362865 | D23: =$F$19*D22 -> 0.42725729 | E23: =$F$19*E22 -> 0.85451458
B24: Container | C24: CONTENER NO : (3) | D24: CONTENER NO : (4) | E24: CONTENER NO : (5)
B25: Container cost | C25: =IFERROR(INDEX(LIST!$G$2:$G$131,MATCH(C24,LIST!$B$2:$B$131,0)),0) -> 0.021 | D25: =IFERROR(INDEX(LIST!$G$2:$G$131,MATCH(D24,LIST!$B$2:$B$131,0)),0) -> 0.0315 | E25: =IFERROR(INDEX(LIST!$G$2:$G$131,MATCH(E24,LIST!$B$2:$B$131,0)),0) -> 0.11666667
B26: Spoons (qty) | C26: 1 | D26: 2 | E26: 3
B27: Spoon cost | C27: =C26*IFERROR(INDEX(LIST!$G$2:$G$131,MATCH("SPOON",LIST!$B$2:$B$131,0)),0) -> 0.0064 | D27: =D26*IFERROR(INDEX(LIST!$G$2:$G$131,MATCH("SPOON",LIST!$B$2:$B$131,0)),0) -> 0.0128 | E27: =E26*IFERROR(INDEX(LIST!$G$2:$G$131,MATCH("SPOON",LIST!$B$2:$B$131,0)),0) -> 0.0192
B28: Bread (qty) | C28: 1 | D28: 2 | E28: 4
B29: Bread cost | C29: =C28*IFERROR(INDEX(LIST!$G$2:$G$131,MATCH("Bread",LIST!$B$2:$B$131,0)),0) -> 0.012 | D29: =D28*IFERROR(INDEX(LIST!$G$2:$G$131,MATCH("Bread",LIST!$B$2:$B$131,0)),0) -> 0.024 | E29: =E28*IFERROR(INDEX(LIST!$G$2:$G$131,MATCH("Bread",LIST!$B$2:$B$131,0)),0) -> 0.048
B30: Bag | C30: Bag Small | D30: Bag Medium | E30: Bag Large
B31: Bag cost | C31: =IFERROR(INDEX(LIST!$G$2:$G$131,MATCH(C30,LIST!$B$2:$B$131,0)),0) -> 0.02 | D31: =IFERROR(INDEX(LIST!$G$2:$G$131,MATCH(D30,LIST!$B$2:$B$131,0)),0) -> 0.03 | E31: =IFERROR(INDEX(LIST!$G$2:$G$131,MATCH(E30,LIST!$B$2:$B$131,0)),0) -> 0.04
B32: Other costs | C32: 0 | D32: 0 | E32: 0
B33: Packaging total | C33: =C25+C27+C29+C31+C32 -> 0.0594 | D33: =D25+D27+D29+D31+D32 -> 0.0983 | E33: =E25+E27+E29+E31+E32 -> 0.22386667
B34: TOTAL COST | C34: =C23+C33 -> 0.27302865 | D34: =D23+D33 -> 0.52555729 | E34: =E23+E33 -> 1.0783812
B35: Store price | C35: 1.2 | D35: 2.2 | E35: 4.2
B36: Store cost % | C36: =IF(C35=0,"",C34/C35) -> 0.22752387 | D36: =IF(D35=0,"",D34/D35) -> 0.23888968 | E36: =IF(E35=0,"",E34/E35) -> 0.25675744
B37: Delivery price | C37: 1.6 | D37: 2.8 | E37: 5
B38: Delivery cost % | C38: =IF(N(C37)=0,"",C34/C37) -> 0.1706429 | D38: =IF(N(D37)=0,"",D34/D37) -> 0.18769903 | E38: =IF(N(E37)=0,"",E34/E37) -> 0.21567625
B39: Store profit | C39: =C35-C34 -> 0.92697135 | D39: =D35-D34 -> 1.6744427 | E39: =E35-E34 -> 3.1216188
B40: Delivery profit | C40: =IF(N(C37)=0,"",C37-C34) -> 1.3269714 | D40: =IF(N(D37)=0,"",D37-D34) -> 2.2744427 | E40: =IF(N(E37)=0,"",E37-E34) -> 3.9216188

Sheet Egg Makhalama
A1: Egg Makhalama
A2: Eggs & fool · one container takes several recipes · target 30%
A4: # | B4: Item | C4: Qty | D4: Unit | E4: Unit price | F4: Cost
A5: 1 | B5: Minced Beef | C5: 30 | D5: =IFERROR(INDEX(LIST!$F$2:$F$131,MATCH(B5,LIST!$B$2:$B$131,0)),"") -> g | E5: =IFERROR(INDEX(LIST!$G$2:$G$131,MATCH(B5,LIST!$B$2:$B$131,0)),0) -> 0.0005975 | F5: =C5*E5 -> 0.017925
A6: 2 | B6: Egg | C6: 2 | D6: =IFERROR(INDEX(LIST!$F$2:$F$131,MATCH(B6,LIST!$B$2:$B$131,0)),"") -> pc | E6: =IFERROR(INDEX(LIST!$G$2:$G$131,MATCH(B6,LIST!$B$2:$B$131,0)),0) -> 0.035 | F6: =C6*E6 -> 0.07
A7: 3 | B7: Vegetable Oil | C7: 15 | D7: =IFERROR(INDEX(LIST!$F$2:$F$131,MATCH(B7,LIST!$B$2:$B$131,0)),"") -> ml | E7: =IFERROR(INDEX(LIST!$G$2:$G$131,MATCH(B7,LIST!$B$2:$B$131,0)),0) -> 0.000594 | F7: =C7*E7 -> 0.00891
A8: 4 | B8: Tomato Paste | C8: 5 | D8: =IFERROR(INDEX(LIST!$F$2:$F$131,MATCH(B8,LIST!$B$2:$B$131,0)),"") -> g | E8: =IFERROR(INDEX(LIST!$G$2:$G$131,MATCH(B8,LIST!$B$2:$B$131,0)),0) -> 0.0006 | F8: =C8*E8 -> 0.003
A9: 5 | B9: Onion | C9: 60 | D9: =IFERROR(INDEX(LIST!$F$2:$F$131,MATCH(B9,LIST!$B$2:$B$131,0)),"") -> g | E9: =IFERROR(INDEX(LIST!$G$2:$G$131,MATCH(B9,LIST!$B$2:$B$131,0)),0) -> 0.00045 | F9: =C9*E9 -> 0.027
A10: 6 | B10: Coriander Leaves | C10: 2 | D10: =IFERROR(INDEX(LIST!$F$2:$F$131,MATCH(B10,LIST!$B$2:$B$131,0)),"") -> g | E10: =IFERROR(INDEX(LIST!$G$2:$G$131,MATCH(B10,LIST!$B$2:$B$131,0)),0) -> 0.0017272727 | F10: =C10*E10 -> 0.0034545455
A11: 7 | B11: Tomato | C11: 120 | D11: =IFERROR(INDEX(LIST!$F$2:$F$131,MATCH(B11,LIST!$B$2:$B$131,0)),"") -> g | E11: =IFERROR(INDEX(LIST!$G$2:$G$131,MATCH(B11,LIST!$B$2:$B$131,0)),0) -> 0.0005 | F11: =C11*E11 -> 0.06
A12: 8 | B12: Green Capiscum | C12: 15 | D12: =IFERROR(INDEX(LIST!$F$2:$F$131,MATCH(B12,LIST!$B$2:$B$131,0)),"") -> g | E12: =IFERROR(INDEX(LIST!$G$2:$G$131,MATCH(B12,LIST!$B$2:$B$131,0)),0) -> 0.00065 | F12: =C12*E12 -> 0.00975
A13: 9 | B13: Turmeric Powder | C13: 1.2 | D13: =IFERROR(INDEX(LIST!$F$2:$F$131,MATCH(B13,LIST!$B$2:$B$131,0)),"") -> g | E13: =IFERROR(INDEX(LIST!$G$2:$G$131,MATCH(B13,LIST!$B$2:$B$131,0)),0) -> 0.0018 | F13: =C13*E13 -> 0.00216
A14: 10 | B14: Cummin Powder | C14: 1.2 | D14: =IFERROR(INDEX(LIST!$F$2:$F$131,MATCH(B14,LIST!$B$2:$B$131,0)),"") -> g | E14: =IFERROR(INDEX(LIST!$G$2:$G$131,MATCH(B14,LIST!$B$2:$B$131,0)),0) -> 0.002818 | F14: =C14*E14 -> 0.0033816
A15: 11 | B15: Tandori Masala Powder | C15: 1.2 | D15: =IFERROR(INDEX(LIST!$F$2:$F$131,MATCH(B15,LIST!$B$2:$B$131,0)),"") -> g | E15: =IFERROR(INDEX(LIST!$G$2:$G$131,MATCH(B15,LIST!$B$2:$B$131,0)),0) -> 0.004 | F15: =C15*E15 -> 0.0048
A16: 12 | B16: Mix Masala Powder | C16: 1.2 | D16: =IFERROR(INDEX(LIST!$F$2:$F$131,MATCH(B16,LIST!$B$2:$B$131,0)),"") -> g | E16: =IFERROR(INDEX(LIST!$G$2:$G$131,MATCH(B16,LIST!$B$2:$B$131,0)),0) -> 0.00165 | F16: =C16*E16 -> 0.00198
... A18: 14 | B18: Salt | C18: 1.2 | D18: =IFERROR(INDEX(LIST!$F$2:$F$131,MATCH(B18,LIST!$B$2:$B$131,0)),"") -> g | E18: =IFERROR(INDEX(LIST!$G$2:$G$131,MATCH(B18,LIST!$B$2:$B$131,0)),0) -> 0.000165 | F18: =C18*E18 -> 0.000198
B19: TOTAL RECIPE COST | F19: =SUM(F5:F18) -> 0.21453915
B21: Size | C21: Small | D21: Medium | E21: Large
B22: Recipes per container | C22: 1 | D22: 2 | E22: 4
B23: Ingredient cost | C23: =$F$19*C22 -> 0.21453915 | D23: =$F$19*D22 -> 0.42907829 | E23: =$F$19*E22 -> 0.85815658
B24: Container | C24: CONTENER NO : (3) | D24: CONTENER NO : (4) | E24: CONTENER NO : (5)
B25: Container cost | C25: =IFERROR(INDEX(LIST!$G$2:$G$131,MATCH(C24,LIST!$B$2:$B$131,0)),0) -> 0.021 | D25: =IFERROR(INDEX(LIST!$G$2:$G$131,MATCH(D24,LIST!$B$2:$B$131,0)),0) -> 0.0315 | E25: =IFERROR(INDEX(LIST!$G$2:$G$131,MATCH(E24,LIST!$B$2:$B$131,0)),0) -> 0.11666667
B26: Spoons (qty) | C26: 1.45 | D26: 4.5 | E26: 6
B27: Spoon cost | C27: =C26*IFERROR(INDEX(LIST!$G$2:$G$131,MATCH("SPOON",LIST!$B$2:$B$131,0)),0) -> 0.00928 | D27: =D26*IFERROR(INDEX(LIST!$G$2:$G$131,MATCH("SPOON",LIST!$B$2:$B$131,0)),0) -> 0.0288 | E27: =E26*IFERROR(INDEX(LIST!$G$2:$G$131,MATCH("SPOON",LIST!$B$2:$B$131,0)),0) -> 0.0384
B28: Bread (qty) | C28: 1 | D28: 2 | E28: 4
B29: Bread cost | C29: =C28*IFERROR(INDEX(LIST!$G$2:$G$131,MATCH("Bread",LIST!$B$2:$B$131,0)),0) -> 0.012 | D29: =D28*IFERROR(INDEX(LIST!$G$2:$G$131,MATCH("Bread",LIST!$B$2:$B$131,0)),0) -> 0.024 | E29: =E28*IFERROR(INDEX(LIST!$G$2:$G$131,MATCH("Bread",LIST!$B$2:$B$131,0)),0) -> 0.048
B30: Bag | C30: Bag Small | D30: Bag Medium | E30: Bag Large
B31: Bag cost | C31: =IFERROR(INDEX(LIST!$G$2:$G$131,MATCH(C30,LIST!$B$2:$B$131,0)),0) -> 0.02 | D31: =IFERROR(INDEX(LIST!$G$2:$G$131,MATCH(D30,LIST!$B$2:$B$131,0)),0) -> 0.03 | E31: =IFERROR(INDEX(LIST!$G$2:$G$131,MATCH(E30,LIST!$B$2:$B$131,0)),0) -> 0.04
B32: Other costs | C32: 0 | D32: 0 | E32: 0
B33: Packaging total | C33: =C25+C27+C29+C31+C32 -> 0.06228 | D33: =D25+D27+D29+D31+D32 -> 0.1143 | E33: =E25+E27+E29+E31+E32 -> 0.24306667
B34: TOTAL COST | C34: =C23+C33 -> 0.27681915 | D34: =D23+D33 -> 0.54337829 | E34: =E23+E33 -> 1.1012232
B35: Store price | C35: 1.4 | D35: 2.6 | E35: 5
B36: Store cost % | C36: =IF(C35=0,"",C34/C35) -> 0.19772796 | D36: =IF(D35=0,"",D34/D35) -> 0.20899165 | E36: =IF(E35=0,"",E34/E35) -> 0.22024465
B37: Delivery price | C37: 1.85 | D37: 3.2 | E37: 6
B38: Delivery cost % | C38: =IF(N(C37)=0,"",C34/C37) -> 0.14963197 | D38: =IF(N(D37)=0,"",D34/D37) -> 0.16980572 | E38: =IF(N(E37)=0,"",E34/E37) -> 0.18353721
B39: Store profit | C39: =C35-C34 -> 1.1231809 | D39: =D35-D34 -> 2.0566217 | E39: =E35-E34 -> 3.8987768
B40: Delivery profit | C40: =IF(N(C37)=0,"",C37-C34) -> 1.5731809 | D40: =IF(N(D37)=0,"",D37-D34) -> 2.6566217 | E40: =IF(N(E37)=0,"",E37-E34) -> 4.8987768

Sheet Egg Cheese
A1: Egg Cheese
A2: Eggs & fool · one container takes several recipes · target 30%
A4: # | B4: Item | C4: Qty | D4: Unit | E4: Unit price | F4: Cost
A5: 1 | B5: Egg | C5: 4 | D5: =IFERROR(INDEX(LIST!$F$2:$F$131,MATCH(B5,LIST!$B$2:$B$131,0)),"") -> pc | E5: =IFERROR(INDEX(LIST!$G$2:$G$131,MATCH(B5,LIST!$B$2:$B$131,0)),0) -> 0.035 | F5: =C5*E5 -> 0.14
